<?xml version="1.0" encoding="utf-8"?>
<!-- This URDF was automatically created by SolidWorks to URDF Exporter! Originally created by Stephen Brawner (brawner@gmail.com) 
     Commit Version: 1.5.1-0-g916b5db  Build Version: 1.5.7152.31018
     For more information, please see http://wiki.ros.org/sw_urdf_exporter -->
<robot
  name="actuator">
  <static>1 0 0</static>

  <link
    name="support">
    <inertial>
      <origin
        xyz="0 0 0"
        rpy="0 0 0" />
      <mass
        value="1000" />
      <inertia
        ixx="1000"
        ixy="0"
        ixz="0"
        iyy="1000"
        iyz="0"
        izz="1000" />
    </inertial>

    <visual>
      <origin
        xyz="0 0 0"
        rpy="0 0 0" />
      <geometry>
				<box size="1 5 0.1"/>
      </geometry>
    </visual>

    <collision>
      <origin
        xyz="0 0 0"
        rpy="0 0 0" />
      <geometry>
				<box size="1 5 0.1"/>
      </geometry>
    </collision>
  </link>

  <joint
    name="support_joint"
    type="fixed">
    <origin
      xyz="0 0 0.75"
      rpy="-3.1416 -1.4241 3.1416" />
    <parent
      link="support" />
    <child
      link="base_link" />
  </joint>

  <link
    name="base_link">
    <inertial>
      <origin
        xyz="0.102698693078248 0.185507014938219 0.237856750752446"
        rpy="0 0 0" />
      <mass
        value="1.69719752173322" />
      <inertia
        ixx="0.00461409373022473"
        ixy="2.10539538122137E-10"
        ixz="-3.27608375773942E-10"
        iyy="0.00506977728038184"
        iyz="-0.00024038463225421"
        izz="0.00164019075800988" />
    </inertial>
    <visual>
      <origin
        xyz="0 0 0"
        rpy="0 0 0" />
      <geometry>
        <mesh
          filename="package://actuator/meshes/base_link.STL" />
      </geometry>
      <material
        name="">
        <color
          rgba="0.666666666666667 0.698039215686274 0.768627450980392 1" />
      </material>
    </visual>
    <collision>
      <origin
        xyz="0 0 0"
        rpy="0 0 0" />
      <geometry>
        <mesh
          filename="package://actuator/meshes/base_link.STL" />
      </geometry>
    </collision>
  </link>

  <link
    name="actuator_rod">
    <inertial>
      <origin
        xyz="-6.12794875953782E-09 0.0860228529586428 -3.0171669812562E-07"
        rpy="0 0 0" />
      <mass
        value="0.141742027033077" />
      <inertia
        ixx="0.1"
        ixy="3.01174317665818E-11"
        ixz="2.43429637951659E-11"
        iyy="0.1"
        iyz="1.19300588695323E-10"
        izz="0.1" />
    </inertial>
    <visual>
      <origin
        xyz="0 0 0"
        rpy="0 0 0" />
      <geometry>
        <mesh
          filename="package://actuator/meshes/actuator rod.STL" />
      </geometry>
      <material
        name="">
        <color
          rgba="0.796078431372549 0.823529411764706 0.937254901960784 1" />
      </material>
    </visual>
    <collision>
      <origin
        xyz="0 0 0"
        rpy="0 0 0" />
      <geometry>
        <mesh
          filename="package://actuator/meshes/actuator rod.STL" />
      </geometry>
    </collision>
  </link>

  <joint
    name="actuator_joint"
    type="prismatic">
    <origin
      xyz="0.1027 -0.47008 0.19302"
      rpy="-3.1416 -1.4241 3.1416" />
    <parent
      link="base_link" />
    <child
      link="actuator_rod" />
    <axis
      xyz="0 1 0" />
    <limit
      lower="-0.2"
      upper="0.2"
      effort="1000"
      velocity="0.5" />
  </joint>

  <transmission name="rod_trans" type="SimpleTransmission">
    <type>transmission_interface/SimpleTransmission</type>
    <actuator name="Rod_Motor">
      <mechanicalReduction>1</mechanicalReduction>
    </actuator>
    <joint name="actuator_joint">
      <hardwareInterface>EffortJointInterface</hardwareInterface>
    </joint>
  </transmission>

  <gazebo>
    <plugin name="gazebo_ros_control" filename="libgazebo_ros_control.so">
    </plugin>
  </gazebo>

</robot>
